[Fri Sep 29 12:26:24.762136 2017] [mpm_event:notice] [pid 3468:tid 139819347257216] AH00489: Apache/2.4.18 (Ubuntu) configured -- resuming normal operations
[Fri Sep 29 12:26:24.762217 2017] [core:notice] [pid 3468:tid 139819347257216] AH00094: Command line: '/usr/sbin/apache2'
[Fri Sep 29 12:51:13.258710 2017] [mpm_event:notice] [pid 3468:tid 139819347257216] AH00491: caught SIGTERM, shutting down
[Fri Sep 29 12:51:14.326595 2017] [wsgi:warn] [pid 4099:tid 139836051924864] mod_wsgi: Compiled for Python/2.7.11.
[Fri Sep 29 12:51:14.326635 2017] [wsgi:warn] [pid 4099:tid 139836051924864] mod_wsgi: Runtime using Python/2.7.12.
[Fri Sep 29 12:51:14.327058 2017] [mpm_event:notice] [pid 4099:tid 139836051924864] AH00489: Apache/2.4.18 (Ubuntu) mod_wsgi/4.3.0 Python/2.7.12 configured -- resuming normal operations
[Fri Sep 29 12:51:14.327073 2017] [core:notice] [pid 4099:tid 139836051924864] AH00094: Command line: '/usr/sbin/apache2'
[Fri Sep 29 13:05:42.847788 2017] [mpm_event:notice] [pid 4099:tid 139836051924864] AH00491: caught SIGTERM, shutting down
[Fri Sep 29 13:05:42.912221 2017] [wsgi:warn] [pid 4275:tid 140040780486528] mod_wsgi: Compiled for Python/2.7.11.
[Fri Sep 29 13:05:42.912253 2017] [wsgi:warn] [pid 4275:tid 140040780486528] mod_wsgi: Runtime using Python/2.7.12.
[Fri Sep 29 13:05:42.912608 2017] [mpm_event:notice] [pid 4275:tid 140040780486528] AH00489: Apache/2.4.18 (Ubuntu) mod_wsgi/4.3.0 Python/2.7.12 configured -- resuming normal operations
[Fri Sep 29 13:05:42.912623 2017] [core:notice] [pid 4275:tid 140040780486528] AH00094: Command line: '/usr/sbin/apache2'
[Fri Sep 29 16:55:01.580782 2017] [mpm_event:notice] [pid 4275:tid 140040780486528] AH00491: caught SIGTERM, shutting down
[Fri Sep 29 16:55:35.256177 2017] [wsgi:warn] [pid 1279:tid 140075551184768] mod_wsgi: Compiled for Python/2.7.11.
[Fri Sep 29 16:55:35.256574 2017] [wsgi:warn] [pid 1279:tid 140075551184768] mod_wsgi: Runtime using Python/2.7.12.
[Fri Sep 29 16:55:35.257113 2017] [mpm_event:notice] [pid 1279:tid 140075551184768] AH00489: Apache/2.4.18 (Ubuntu) mod_wsgi/4.3.0 Python/2.7.12 configured -- resuming normal operations
[Fri Sep 29 16:55:35.257134 2017] [core:notice] [pid 1279:tid 140075551184768] AH00094: Command line: '/usr/sbin/apache2'
[Fri Sep 29 16:59:38.981341 2017] [mpm_event:notice] [pid 1279:tid 140075551184768] AH00491: caught SIGTERM, shutting down
[Fri Sep 29 16:59:40.051761 2017] [wsgi:warn] [pid 1511:tid 140431515240320] mod_wsgi: Compiled for Python/2.7.11.
[Fri Sep 29 16:59:40.051798 2017] [wsgi:warn] [pid 1511:tid 140431515240320] mod_wsgi: Runtime using Python/2.7.12.
[Fri Sep 29 16:59:40.052363 2017] [mpm_event:notice] [pid 1511:tid 140431515240320] AH00489: Apache/2.4.18 (Ubuntu) mod_wsgi/4.3.0 Python/2.7.12 configured -- resuming normal operations
[Fri Sep 29 16:59:40.052380 2017] [core:notice] [pid 1511:tid 140431515240320] AH00094: Command line: '/usr/sbin/apache2'
[Fri Sep 29 16:59:57.880927 2017] [wsgi:error] [pid 1514:tid 140431406843648] [remote 155.35.47.150:40116] mod_wsgi (pid=1514): Target WSGI script '/home/ubuntu/website/website/wsgi.py' cannot be loaded as Python module.
[Fri Sep 29 16:59:57.880958 2017] [wsgi:error] [pid 1514:tid 140431406843648] [remote 155.35.47.150:40116] mod_wsgi (pid=1514): Exception occurred processing WSGI script '/home/ubuntu/website/website/wsgi.py'.
[Fri Sep 29 16:59:57.880977 2017] [wsgi:error] [pid 1514:tid 140431406843648] [remote 155.35.47.150:40116] Traceback (most recent call last):
[Fri Sep 29 16:59:57.880992 2017] [wsgi:error] [pid 1514:tid 140431406843648] [remote 155.35.47.150:40116]   File "/home/ubuntu/website/website/wsgi.py", line 16, in <module>
[Fri Sep 29 16:59:57.881036 2017] [wsgi:error] [pid 1514:tid 140431406843648] [remote 155.35.47.150:40116]     application = get_wsgi_application()
[Fri Sep 29 16:59:57.881045 2017] [wsgi:error] [pid 1514:tid 140431406843648] [remote 155.35.47.150:40116]   File "/usr/local/lib/python2.7/dist-packages/django/core/wsgi.py", line 13, in get_wsgi_application
[Fri Sep 29 16:59:57.881608 2017] [wsgi:error] [pid 1514:tid 140431406843648] [remote 155.35.47.150:40116]     django.setup()
[Fri Sep 29 16:59:57.881628 2017] [wsgi:error] [pid 1514:tid 140431406843648] [remote 155.35.47.150:40116]   File "/usr/local/lib/python2.7/dist-packages/django/__init__.py", line 17, in setup
[Fri Sep 29 16:59:57.882224 2017] [wsgi:error] [pid 1514:tid 140431406843648] [remote 155.35.47.150:40116]     configure_logging(settings.LOGGING_CONFIG, settings.LOGGING)
[Fri Sep 29 16:59:57.882234 2017] [wsgi:error] [pid 1514:tid 140431406843648] [remote 155.35.47.150:40116]   File "/usr/local/lib/python2.7/dist-packages/django/conf/__init__.py", line 55, in __getattr__
[Fri Sep 29 16:59:57.882878 2017] [wsgi:error] [pid 1514:tid 140431406843648] [remote 155.35.47.150:40116]     self._setup(name)
[Fri Sep 29 16:59:57.882889 2017] [wsgi:error] [pid 1514:tid 140431406843648] [remote 155.35.47.150:40116]   File "/usr/local/lib/python2.7/dist-packages/django/conf/__init__.py", line 43, in _setup
[Fri Sep 29 16:59:57.882903 2017] [wsgi:error] [pid 1514:tid 140431406843648] [remote 155.35.47.150:40116]     self._wrapped = Settings(settings_module)
[Fri Sep 29 16:59:57.882907 2017] [wsgi:error] [pid 1514:tid 140431406843648] [remote 155.35.47.150:40116]   File "/usr/local/lib/python2.7/dist-packages/django/conf/__init__.py", line 99, in __init__
[Fri Sep 29 16:59:57.882915 2017] [wsgi:error] [pid 1514:tid 140431406843648] [remote 155.35.47.150:40116]     mod = importlib.import_module(self.SETTINGS_MODULE)
[Fri Sep 29 16:59:57.882919 2017] [wsgi:error] [pid 1514:tid 140431406843648] [remote 155.35.47.150:40116]   File "/usr/lib/python2.7/importlib/__init__.py", line 37, in import_module
[Fri Sep 29 16:59:57.883510 2017] [wsgi:error] [pid 1514:tid 140431406843648] [remote 155.35.47.150:40116]     __import__(name)
[Fri Sep 29 16:59:57.883529 2017] [wsgi:error] [pid 1514:tid 140431406843648] [remote 155.35.47.150:40116] ImportError: No module named website.settings
[Fri Sep 29 17:00:19.553802 2017] [wsgi:error] [pid 1514:tid 140431289255680] [remote 155.35.47.150:37812] mod_wsgi (pid=1514): Target WSGI script '/home/ubuntu/website/website/wsgi.py' cannot be loaded as Python module.
[Fri Sep 29 17:00:19.553833 2017] [wsgi:error] [pid 1514:tid 140431289255680] [remote 155.35.47.150:37812] mod_wsgi (pid=1514): Exception occurred processing WSGI script '/home/ubuntu/website/website/wsgi.py'.
[Fri Sep 29 17:00:19.553850 2017] [wsgi:error] [pid 1514:tid 140431289255680] [remote 155.35.47.150:37812] Traceback (most recent call last):
[Fri Sep 29 17:00:19.553868 2017] [wsgi:error] [pid 1514:tid 140431289255680] [remote 155.35.47.150:37812]   File "/home/ubuntu/website/website/wsgi.py", line 16, in <module>
[Fri Sep 29 17:00:19.553891 2017] [wsgi:error] [pid 1514:tid 140431289255680] [remote 155.35.47.150:37812]     application = get_wsgi_application()
[Fri Sep 29 17:00:19.553898 2017] [wsgi:error] [pid 1514:tid 140431289255680] [remote 155.35.47.150:37812]   File "/usr/local/lib/python2.7/dist-packages/django/core/wsgi.py", line 13, in get_wsgi_application
[Fri Sep 29 17:00:19.553908 2017] [wsgi:error] [pid 1514:tid 140431289255680] [remote 155.35.47.150:37812]     django.setup()
[Fri Sep 29 17:00:19.553914 2017] [wsgi:error] [pid 1514:tid 140431289255680] [remote 155.35.47.150:37812]   File "/usr/local/lib/python2.7/dist-packages/django/__init__.py", line 17, in setup
[Fri Sep 29 17:00:19.553922 2017] [wsgi:error] [pid 1514:tid 140431289255680] [remote 155.35.47.150:37812]     configure_logging(settings.LOGGING_CONFIG, settings.LOGGING)
[Fri Sep 29 17:00:19.553927 2017] [wsgi:error] [pid 1514:tid 140431289255680] [remote 155.35.47.150:37812]   File "/usr/local/lib/python2.7/dist-packages/django/conf/__init__.py", line 55, in __getattr__
[Fri Sep 29 17:00:19.553935 2017] [wsgi:error] [pid 1514:tid 140431289255680] [remote 155.35.47.150:37812]     self._setup(name)
[Fri Sep 29 17:00:19.553940 2017] [wsgi:error] [pid 1514:tid 140431289255680] [remote 155.35.47.150:37812]   File "/usr/local/lib/python2.7/dist-packages/django/conf/__init__.py", line 43, in _setup
[Fri Sep 29 17:00:19.553952 2017] [wsgi:error] [pid 1514:tid 140431289255680] [remote 155.35.47.150:37812]     self._wrapped = Settings(settings_module)
[Fri Sep 29 17:00:19.553966 2017] [wsgi:error] [pid 1514:tid 140431289255680] [remote 155.35.47.150:37812]   File "/usr/local/lib/python2.7/dist-packages/django/conf/__init__.py", line 99, in __init__
[Fri Sep 29 17:00:19.553974 2017] [wsgi:error] [pid 1514:tid 140431289255680] [remote 155.35.47.150:37812]     mod = importlib.import_module(self.SETTINGS_MODULE)
[Fri Sep 29 17:00:19.553979 2017] [wsgi:error] [pid 1514:tid 140431289255680] [remote 155.35.47.150:37812]   File "/usr/lib/python2.7/importlib/__init__.py", line 37, in import_module
[Fri Sep 29 17:00:19.553986 2017] [wsgi:error] [pid 1514:tid 140431289255680] [remote 155.35.47.150:37812]     __import__(name)
[Fri Sep 29 17:00:19.554000 2017] [wsgi:error] [pid 1514:tid 140431289255680] [remote 155.35.47.150:37812] ImportError: No module named website.settings
[Fri Sep 29 17:07:46.801313 2017] [wsgi:error] [pid 1514:tid 140431406843648] [remote 155.35.47.150:31170] mod_wsgi (pid=1514): Target WSGI script '/home/ubuntu/website/website/wsgi.py' cannot be loaded as Python module.
[Fri Sep 29 17:07:46.801341 2017] [wsgi:error] [pid 1514:tid 140431406843648] [remote 155.35.47.150:31170] mod_wsgi (pid=1514): Exception occurred processing WSGI script '/home/ubuntu/website/website/wsgi.py'.
[Fri Sep 29 17:07:46.801357 2017] [wsgi:error] [pid 1514:tid 140431406843648] [remote 155.35.47.150:31170] Traceback (most recent call last):
[Fri Sep 29 17:07:46.801374 2017] [wsgi:error] [pid 1514:tid 140431406843648] [remote 155.35.47.150:31170]   File "/home/ubuntu/website/website/wsgi.py", line 16, in <module>
[Fri Sep 29 17:07:46.801396 2017] [wsgi:error] [pid 1514:tid 140431406843648] [remote 155.35.47.150:31170]     application = get_wsgi_application()
[Fri Sep 29 17:07:46.801403 2017] [wsgi:error] [pid 1514:tid 140431406843648] [remote 155.35.47.150:31170]   File "/usr/local/lib/python2.7/dist-packages/django/core/wsgi.py", line 13, in get_wsgi_application
[Fri Sep 29 17:07:46.801413 2017] [wsgi:error] [pid 1514:tid 140431406843648] [remote 155.35.47.150:31170]     django.setup()
[Fri Sep 29 17:07:46.801418 2017] [wsgi:error] [pid 1514:tid 140431406843648] [remote 155.35.47.150:31170]   File "/usr/local/lib/python2.7/dist-packages/django/__init__.py", line 17, in setup
[Fri Sep 29 17:07:46.801426 2017] [wsgi:error] [pid 1514:tid 140431406843648] [remote 155.35.47.150:31170]     configure_logging(settings.LOGGING_CONFIG, settings.LOGGING)
[Fri Sep 29 17:07:46.801431 2017] [wsgi:error] [pid 1514:tid 140431406843648] [remote 155.35.47.150:31170]   File "/usr/local/lib/python2.7/dist-packages/django/conf/__init__.py", line 55, in __getattr__
[Fri Sep 29 17:07:46.801439 2017] [wsgi:error] [pid 1514:tid 140431406843648] [remote 155.35.47.150:31170]     self._setup(name)
[Fri Sep 29 17:07:46.801444 2017] [wsgi:error] [pid 1514:tid 140431406843648] [remote 155.35.47.150:31170]   File "/usr/local/lib/python2.7/dist-packages/django/conf/__init__.py", line 43, in _setup
[Fri Sep 29 17:07:46.801450 2017] [wsgi:error] [pid 1514:tid 140431406843648] [remote 155.35.47.150:31170]     self._wrapped = Settings(settings_module)
[Fri Sep 29 17:07:46.801455 2017] [wsgi:error] [pid 1514:tid 140431406843648] [remote 155.35.47.150:31170]   File "/usr/local/lib/python2.7/dist-packages/django/conf/__init__.py", line 99, in __init__
[Fri Sep 29 17:07:46.801461 2017] [wsgi:error] [pid 1514:tid 140431406843648] [remote 155.35.47.150:31170]     mod = importlib.import_module(self.SETTINGS_MODULE)
[Fri Sep 29 17:07:46.801466 2017] [wsgi:error] [pid 1514:tid 140431406843648] [remote 155.35.47.150:31170]   File "/usr/lib/python2.7/importlib/__init__.py", line 37, in import_module
[Fri Sep 29 17:07:46.801473 2017] [wsgi:error] [pid 1514:tid 140431406843648] [remote 155.35.47.150:31170]     __import__(name)
[Fri Sep 29 17:07:46.801487 2017] [wsgi:error] [pid 1514:tid 140431406843648] [remote 155.35.47.150:31170] ImportError: No module named website.settings
[Fri Sep 29 17:11:16.052476 2017] [mpm_event:notice] [pid 1511:tid 140431515240320] AH00491: caught SIGTERM, shutting down
[Fri Sep 29 17:11:16.137599 2017] [wsgi:warn] [pid 1831:tid 139937614399360] mod_wsgi: Compiled for Python/2.7.11.
[Fri Sep 29 17:11:16.137638 2017] [wsgi:warn] [pid 1831:tid 139937614399360] mod_wsgi: Runtime using Python/2.7.12.
[Fri Sep 29 17:11:16.138232 2017] [mpm_event:notice] [pid 1831:tid 139937614399360] AH00489: Apache/2.4.18 (Ubuntu) mod_wsgi/4.3.0 Python/2.7.12 configured -- resuming normal operations
[Fri Sep 29 17:11:16.138249 2017] [core:notice] [pid 1831:tid 139937614399360] AH00094: Command line: '/usr/sbin/apache2'
[Fri Sep 29 17:11:22.902537 2017] [wsgi:error] [pid 1834:tid 139937506002688] [remote 155.35.47.150:54197] mod_wsgi (pid=1834): Target WSGI script '/home/ubuntu/website/website/wsgi.py' cannot be loaded as Python module.
[Fri Sep 29 17:11:22.902590 2017] [wsgi:error] [pid 1834:tid 139937506002688] [remote 155.35.47.150:54197] mod_wsgi (pid=1834): Exception occurred processing WSGI script '/home/ubuntu/website/website/wsgi.py'.
[Fri Sep 29 17:11:22.902610 2017] [wsgi:error] [pid 1834:tid 139937506002688] [remote 155.35.47.150:54197] Traceback (most recent call last):
[Fri Sep 29 17:11:22.902626 2017] [wsgi:error] [pid 1834:tid 139937506002688] [remote 155.35.47.150:54197]   File "/home/ubuntu/website/website/wsgi.py", line 16, in <module>
[Fri Sep 29 17:11:22.902672 2017] [wsgi:error] [pid 1834:tid 139937506002688] [remote 155.35.47.150:54197]     application = get_wsgi_application()
[Fri Sep 29 17:11:22.902680 2017] [wsgi:error] [pid 1834:tid 139937506002688] [remote 155.35.47.150:54197]   File "/home/ubuntu/dev/lib/python3.5/site-packages/django/core/wsgi.py", line 13, in get_wsgi_application
[Fri Sep 29 17:11:22.902705 2017] [wsgi:error] [pid 1834:tid 139937506002688] [remote 155.35.47.150:54197]     django.setup()
[Fri Sep 29 17:11:22.902712 2017] [wsgi:error] [pid 1834:tid 139937506002688] [remote 155.35.47.150:54197]   File "/home/ubuntu/dev/lib/python3.5/site-packages/django/__init__.py", line 17, in setup
[Fri Sep 29 17:11:22.902733 2017] [wsgi:error] [pid 1834:tid 139937506002688] [remote 155.35.47.150:54197]     configure_logging(settings.LOGGING_CONFIG, settings.LOGGING)
[Fri Sep 29 17:11:22.902741 2017] [wsgi:error] [pid 1834:tid 139937506002688] [remote 155.35.47.150:54197]   File "/home/ubuntu/dev/lib/python3.5/site-packages/django/conf/__init__.py", line 55, in __getattr__
[Fri Sep 29 17:11:22.902794 2017] [wsgi:error] [pid 1834:tid 139937506002688] [remote 155.35.47.150:54197]     self._setup(name)
[Fri Sep 29 17:11:22.902801 2017] [wsgi:error] [pid 1834:tid 139937506002688] [remote 155.35.47.150:54197]   File "/home/ubuntu/dev/lib/python3.5/site-packages/django/conf/__init__.py", line 43, in _setup
[Fri Sep 29 17:11:22.902813 2017] [wsgi:error] [pid 1834:tid 139937506002688] [remote 155.35.47.150:54197]     self._wrapped = Settings(settings_module)
[Fri Sep 29 17:11:22.902818 2017] [wsgi:error] [pid 1834:tid 139937506002688] [remote 155.35.47.150:54197]   File "/home/ubuntu/dev/lib/python3.5/site-packages/django/conf/__init__.py", line 99, in __init__
[Fri Sep 29 17:11:22.902826 2017] [wsgi:error] [pid 1834:tid 139937506002688] [remote 155.35.47.150:54197]     mod = importlib.import_module(self.SETTINGS_MODULE)
[Fri Sep 29 17:11:22.902831 2017] [wsgi:error] [pid 1834:tid 139937506002688] [remote 155.35.47.150:54197]   File "/usr/lib/python2.7/importlib/__init__.py", line 37, in import_module
[Fri Sep 29 17:11:22.902855 2017] [wsgi:error] [pid 1834:tid 139937506002688] [remote 155.35.47.150:54197]     __import__(name)
[Fri Sep 29 17:11:22.902870 2017] [wsgi:error] [pid 1834:tid 139937506002688] [remote 155.35.47.150:54197] ImportError: No module named website.settings
[Fri Sep 29 17:11:26.327863 2017] [wsgi:error] [pid 1834:tid 139937388414720] [remote 155.35.47.150:53173] mod_wsgi (pid=1834): Target WSGI script '/home/ubuntu/website/website/wsgi.py' cannot be loaded as Python module.
[Fri Sep 29 17:11:26.327893 2017] [wsgi:error] [pid 1834:tid 139937388414720] [remote 155.35.47.150:53173] mod_wsgi (pid=1834): Exception occurred processing WSGI script '/home/ubuntu/website/website/wsgi.py'.
[Fri Sep 29 17:11:26.327918 2017] [wsgi:error] [pid 1834:tid 139937388414720] [remote 155.35.47.150:53173] Traceback (most recent call last):
[Fri Sep 29 17:11:26.327936 2017] [wsgi:error] [pid 1834:tid 139937388414720] [remote 155.35.47.150:53173]   File "/home/ubuntu/website/website/wsgi.py", line 16, in <module>
[Fri Sep 29 17:11:26.327959 2017] [wsgi:error] [pid 1834:tid 139937388414720] [remote 155.35.47.150:53173]     application = get_wsgi_application()
[Fri Sep 29 17:11:26.327966 2017] [wsgi:error] [pid 1834:tid 139937388414720] [remote 155.35.47.150:53173]   File "/home/ubuntu/dev/lib/python3.5/site-packages/django/core/wsgi.py", line 13, in get_wsgi_application
[Fri Sep 29 17:11:26.327976 2017] [wsgi:error] [pid 1834:tid 139937388414720] [remote 155.35.47.150:53173]     django.setup()
[Fri Sep 29 17:11:26.327982 2017] [wsgi:error] [pid 1834:tid 139937388414720] [remote 155.35.47.150:53173]   File "/home/ubuntu/dev/lib/python3.5/site-packages/django/__init__.py", line 17, in setup
[Fri Sep 29 17:11:26.327990 2017] [wsgi:error] [pid 1834:tid 139937388414720] [remote 155.35.47.150:53173]     configure_logging(settings.LOGGING_CONFIG, settings.LOGGING)
[Fri Sep 29 17:11:26.327995 2017] [wsgi:error] [pid 1834:tid 139937388414720] [remote 155.35.47.150:53173]   File "/home/ubuntu/dev/lib/python3.5/site-packages/django/conf/__init__.py", line 55, in __getattr__
[Fri Sep 29 17:11:26.328004 2017] [wsgi:error] [pid 1834:tid 139937388414720] [remote 155.35.47.150:53173]     self._setup(name)
[Fri Sep 29 17:11:26.328008 2017] [wsgi:error] [pid 1834:tid 139937388414720] [remote 155.35.47.150:53173]   File "/home/ubuntu/dev/lib/python3.5/site-packages/django/conf/__init__.py", line 43, in _setup
[Fri Sep 29 17:11:26.328016 2017] [wsgi:error] [pid 1834:tid 139937388414720] [remote 155.35.47.150:53173]     self._wrapped = Settings(settings_module)
[Fri Sep 29 17:11:26.328021 2017] [wsgi:error] [pid 1834:tid 139937388414720] [remote 155.35.47.150:53173]   File "/home/ubuntu/dev/lib/python3.5/site-packages/django/conf/__init__.py", line 99, in __init__
[Fri Sep 29 17:11:26.328028 2017] [wsgi:error] [pid 1834:tid 139937388414720] [remote 155.35.47.150:53173]     mod = importlib.import_module(self.SETTINGS_MODULE)
[Fri Sep 29 17:11:26.328033 2017] [wsgi:error] [pid 1834:tid 139937388414720] [remote 155.35.47.150:53173]   File "/usr/lib/python2.7/importlib/__init__.py", line 37, in import_module
[Fri Sep 29 17:11:26.328045 2017] [wsgi:error] [pid 1834:tid 139937388414720] [remote 155.35.47.150:53173]     __import__(name)
[Fri Sep 29 17:11:26.328059 2017] [wsgi:error] [pid 1834:tid 139937388414720] [remote 155.35.47.150:53173] ImportError: No module named website.settings
[Fri Sep 29 17:19:05.985551 2017] [mpm_event:notice] [pid 1831:tid 139937614399360] AH00491: caught SIGTERM, shutting down
[Fri Sep 29 17:19:06.075289 2017] [wsgi:warn] [pid 2038:tid 140268534572928] mod_wsgi: Compiled for Python/2.7.11.
[Fri Sep 29 17:19:06.075334 2017] [wsgi:warn] [pid 2038:tid 140268534572928] mod_wsgi: Runtime using Python/2.7.12.
[Fri Sep 29 17:19:06.075854 2017] [mpm_event:notice] [pid 2038:tid 140268534572928] AH00489: Apache/2.4.18 (Ubuntu) mod_wsgi/4.3.0 Python/2.7.12 configured -- resuming normal operations
[Fri Sep 29 17:19:06.075873 2017] [core:notice] [pid 2038:tid 140268534572928] AH00094: Command line: '/usr/sbin/apache2'
[Fri Sep 29 17:19:16.374302 2017] [wsgi:error] [pid 2041:tid 140268426176256] [remote 155.35.47.150:13506] mod_wsgi (pid=2041): Target WSGI script '/home/ubuntu/website/website/wsgi.py' cannot be loaded as Python module.
[Fri Sep 29 17:19:16.374337 2017] [wsgi:error] [pid 2041:tid 140268426176256] [remote 155.35.47.150:13506] mod_wsgi (pid=2041): Exception occurred processing WSGI script '/home/ubuntu/website/website/wsgi.py'.
[Fri Sep 29 17:19:16.374356 2017] [wsgi:error] [pid 2041:tid 140268426176256] [remote 155.35.47.150:13506] Traceback (most recent call last):
[Fri Sep 29 17:19:16.374370 2017] [wsgi:error] [pid 2041:tid 140268426176256] [remote 155.35.47.150:13506]   File "/home/ubuntu/website/website/wsgi.py", line 16, in <module>
[Fri Sep 29 17:19:16.374423 2017] [wsgi:error] [pid 2041:tid 140268426176256] [remote 155.35.47.150:13506]     application = get_wsgi_application()
[Fri Sep 29 17:19:16.374432 2017] [wsgi:error] [pid 2041:tid 140268426176256] [remote 155.35.47.150:13506]   File "/usr/local/lib/python2.7/dist-packages/django/core/wsgi.py", line 13, in get_wsgi_application
[Fri Sep 29 17:19:16.374456 2017] [wsgi:error] [pid 2041:tid 140268426176256] [remote 155.35.47.150:13506]     django.setup()
[Fri Sep 29 17:19:16.374465 2017] [wsgi:error] [pid 2041:tid 140268426176256] [remote 155.35.47.150:13506]   File "/usr/local/lib/python2.7/dist-packages/django/__init__.py", line 17, in setup
[Fri Sep 29 17:19:16.374486 2017] [wsgi:error] [pid 2041:tid 140268426176256] [remote 155.35.47.150:13506]     configure_logging(settings.LOGGING_CONFIG, settings.LOGGING)
[Fri Sep 29 17:19:16.374493 2017] [wsgi:error] [pid 2041:tid 140268426176256] [remote 155.35.47.150:13506]   File "/usr/local/lib/python2.7/dist-packages/django/conf/__init__.py", line 55, in __getattr__
[Fri Sep 29 17:19:16.374580 2017] [wsgi:error] [pid 2041:tid 140268426176256] [remote 155.35.47.150:13506]     self._setup(name)
[Fri Sep 29 17:19:16.374590 2017] [wsgi:error] [pid 2041:tid 140268426176256] [remote 155.35.47.150:13506]   File "/usr/local/lib/python2.7/dist-packages/django/conf/__init__.py", line 43, in _setup
[Fri Sep 29 17:19:16.374603 2017] [wsgi:error] [pid 2041:tid 140268426176256] [remote 155.35.47.150:13506]     self._wrapped = Settings(settings_module)
[Fri Sep 29 17:19:16.374608 2017] [wsgi:error] [pid 2041:tid 140268426176256] [remote 155.35.47.150:13506]   File "/usr/local/lib/python2.7/dist-packages/django/conf/__init__.py", line 99, in __init__
[Fri Sep 29 17:19:16.374616 2017] [wsgi:error] [pid 2041:tid 140268426176256] [remote 155.35.47.150:13506]     mod = importlib.import_module(self.SETTINGS_MODULE)
[Fri Sep 29 17:19:16.374621 2017] [wsgi:error] [pid 2041:tid 140268426176256] [remote 155.35.47.150:13506]   File "/usr/lib/python2.7/importlib/__init__.py", line 37, in import_module
[Fri Sep 29 17:19:16.374647 2017] [wsgi:error] [pid 2041:tid 140268426176256] [remote 155.35.47.150:13506]     __import__(name)
[Fri Sep 29 17:19:16.374663 2017] [wsgi:error] [pid 2041:tid 140268426176256] [remote 155.35.47.150:13506] ImportError: No module named website.settings
[Fri Sep 29 17:19:28.420908 2017] [wsgi:error] [pid 2041:tid 140268308588288] [remote 155.35.47.150:12482] mod_wsgi (pid=2041): Target WSGI script '/home/ubuntu/website/website/wsgi.py' cannot be loaded as Python module.
[Fri Sep 29 17:19:28.420937 2017] [wsgi:error] [pid 2041:tid 140268308588288] [remote 155.35.47.150:12482] mod_wsgi (pid=2041): Exception occurred processing WSGI script '/home/ubuntu/website/website/wsgi.py'.
[Fri Sep 29 17:19:28.420955 2017] [wsgi:error] [pid 2041:tid 140268308588288] [remote 155.35.47.150:12482] Traceback (most recent call last):
[Fri Sep 29 17:19:28.420972 2017] [wsgi:error] [pid 2041:tid 140268308588288] [remote 155.35.47.150:12482]   File "/home/ubuntu/website/website/wsgi.py", line 16, in <module>
[Fri Sep 29 17:19:28.420996 2017] [wsgi:error] [pid 2041:tid 140268308588288] [remote 155.35.47.150:12482]     application = get_wsgi_application()
[Fri Sep 29 17:19:28.421003 2017] [wsgi:error] [pid 2041:tid 140268308588288] [remote 155.35.47.150:12482]   File "/usr/local/lib/python2.7/dist-packages/django/core/wsgi.py", line 13, in get_wsgi_application
[Fri Sep 29 17:19:28.421013 2017] [wsgi:error] [pid 2041:tid 140268308588288] [remote 155.35.47.150:12482]     django.setup()
[Fri Sep 29 17:19:28.421019 2017] [wsgi:error] [pid 2041:tid 140268308588288] [remote 155.35.47.150:12482]   File "/usr/local/lib/python2.7/dist-packages/django/__init__.py", line 17, in setup
[Fri Sep 29 17:19:28.421027 2017] [wsgi:error] [pid 2041:tid 140268308588288] [remote 155.35.47.150:12482]     configure_logging(settings.LOGGING_CONFIG, settings.LOGGING)
[Fri Sep 29 17:19:28.421034 2017] [wsgi:error] [pid 2041:tid 140268308588288] [remote 155.35.47.150:12482]   File "/usr/local/lib/python2.7/dist-packages/django/conf/__init__.py", line 55, in __getattr__
[Fri Sep 29 17:19:28.421051 2017] [wsgi:error] [pid 2041:tid 140268308588288] [remote 155.35.47.150:12482]     self._setup(name)
[Fri Sep 29 17:19:28.421057 2017] [wsgi:error] [pid 2041:tid 140268308588288] [remote 155.35.47.150:12482]   File "/usr/local/lib/python2.7/dist-packages/django/conf/__init__.py", line 43, in _setup
[Fri Sep 29 17:19:28.421064 2017] [wsgi:error] [pid 2041:tid 140268308588288] [remote 155.35.47.150:12482]     self._wrapped = Settings(settings_module)
[Fri Sep 29 17:19:28.421069 2017] [wsgi:error] [pid 2041:tid 140268308588288] [remote 155.35.47.150:12482]   File "/usr/local/lib/python2.7/dist-packages/django/conf/__init__.py", line 99, in __init__
[Fri Sep 29 17:19:28.421076 2017] [wsgi:error] [pid 2041:tid 140268308588288] [remote 155.35.47.150:12482]     mod = importlib.import_module(self.SETTINGS_MODULE)
[Fri Sep 29 17:19:28.421082 2017] [wsgi:error] [pid 2041:tid 140268308588288] [remote 155.35.47.150:12482]   File "/usr/lib/python2.7/importlib/__init__.py", line 37, in import_module
[Fri Sep 29 17:19:28.421090 2017] [wsgi:error] [pid 2041:tid 140268308588288] [remote 155.35.47.150:12482]     __import__(name)
[Fri Sep 29 17:19:28.421106 2017] [wsgi:error] [pid 2041:tid 140268308588288] [remote 155.35.47.150:12482] ImportError: No module named website.settings
[Fri Sep 29 17:35:25.426612 2017] [mpm_event:notice] [pid 2038:tid 140268534572928] AH00491: caught SIGTERM, shutting down
[Fri Sep 29 17:35:25.507238 2017] [wsgi:warn] [pid 2229:tid 139879453202304] mod_wsgi: Compiled for Python/2.7.11.
[Fri Sep 29 17:35:25.507276 2017] [wsgi:warn] [pid 2229:tid 139879453202304] mod_wsgi: Runtime using Python/2.7.12.
[Fri Sep 29 17:35:25.507889 2017] [mpm_event:notice] [pid 2229:tid 139879453202304] AH00489: Apache/2.4.18 (Ubuntu) mod_wsgi/4.3.0 Python/2.7.12 configured -- resuming normal operations
[Fri Sep 29 17:35:25.507905 2017] [core:notice] [pid 2229:tid 139879453202304] AH00094: Command line: '/usr/sbin/apache2'
[Fri Sep 29 17:35:33.620558 2017] [wsgi:error] [pid 2232:tid 139879344805632] [remote 155.35.47.150:9771] mod_wsgi (pid=2232): Target WSGI script '/home/ubuntu/src/website/wsgi.py' cannot be loaded as Python module.
[Fri Sep 29 17:35:33.620589 2017] [wsgi:error] [pid 2232:tid 139879344805632] [remote 155.35.47.150:9771] mod_wsgi (pid=2232): Exception occurred processing WSGI script '/home/ubuntu/src/website/wsgi.py'.
[Fri Sep 29 17:35:33.620608 2017] [wsgi:error] [pid 2232:tid 139879344805632] [remote 155.35.47.150:9771] Traceback (most recent call last):
[Fri Sep 29 17:35:33.620623 2017] [wsgi:error] [pid 2232:tid 139879344805632] [remote 155.35.47.150:9771]   File "/home/ubuntu/src/website/wsgi.py", line 16, in <module>
[Fri Sep 29 17:35:33.620665 2017] [wsgi:error] [pid 2232:tid 139879344805632] [remote 155.35.47.150:9771]     application = get_wsgi_application()
[Fri Sep 29 17:35:33.620674 2017] [wsgi:error] [pid 2232:tid 139879344805632] [remote 155.35.47.150:9771]   File "/home/ubuntu/dev/lib/python3.5/site-packages/django/core/wsgi.py", line 13, in get_wsgi_application
[Fri Sep 29 17:35:33.620696 2017] [wsgi:error] [pid 2232:tid 139879344805632] [remote 155.35.47.150:9771]     django.setup()
[Fri Sep 29 17:35:33.620703 2017] [wsgi:error] [pid 2232:tid 139879344805632] [remote 155.35.47.150:9771]   File "/home/ubuntu/dev/lib/python3.5/site-packages/django/__init__.py", line 17, in setup
[Fri Sep 29 17:35:33.620723 2017] [wsgi:error] [pid 2232:tid 139879344805632] [remote 155.35.47.150:9771]     configure_logging(settings.LOGGING_CONFIG, settings.LOGGING)
[Fri Sep 29 17:35:33.620731 2017] [wsgi:error] [pid 2232:tid 139879344805632] [remote 155.35.47.150:9771]   File "/home/ubuntu/dev/lib/python3.5/site-packages/django/conf/__init__.py", line 55, in __getattr__
[Fri Sep 29 17:35:33.620781 2017] [wsgi:error] [pid 2232:tid 139879344805632] [remote 155.35.47.150:9771]     self._setup(name)
[Fri Sep 29 17:35:33.620788 2017] [wsgi:error] [pid 2232:tid 139879344805632] [remote 155.35.47.150:9771]   File "/home/ubuntu/dev/lib/python3.5/site-packages/django/conf/__init__.py", line 43, in _setup
[Fri Sep 29 17:35:33.620821 2017] [wsgi:error] [pid 2232:tid 139879344805632] [remote 155.35.47.150:9771]     self._wrapped = Settings(settings_module)
[Fri Sep 29 17:35:33.620827 2017] [wsgi:error] [pid 2232:tid 139879344805632] [remote 155.35.47.150:9771]   File "/home/ubuntu/dev/lib/python3.5/site-packages/django/conf/__init__.py", line 99, in __init__
[Fri Sep 29 17:35:33.620835 2017] [wsgi:error] [pid 2232:tid 139879344805632] [remote 155.35.47.150:9771]     mod = importlib.import_module(self.SETTINGS_MODULE)
[Fri Sep 29 17:35:33.620839 2017] [wsgi:error] [pid 2232:tid 139879344805632] [remote 155.35.47.150:9771]   File "/usr/lib/python2.7/importlib/__init__.py", line 37, in import_module
[Fri Sep 29 17:35:33.620863 2017] [wsgi:error] [pid 2232:tid 139879344805632] [remote 155.35.47.150:9771]     __import__(name)
[Fri Sep 29 17:35:33.620878 2017] [wsgi:error] [pid 2232:tid 139879344805632] [remote 155.35.47.150:9771] ImportError: No module named website.settings
[Fri Sep 29 17:35:36.041124 2017] [wsgi:error] [pid 2232:tid 139879227217664] [remote 155.35.47.150:9515] mod_wsgi (pid=2232): Target WSGI script '/home/ubuntu/src/website/wsgi.py' cannot be loaded as Python module.
[Fri Sep 29 17:35:36.041152 2017] [wsgi:error] [pid 2232:tid 139879227217664] [remote 155.35.47.150:9515] mod_wsgi (pid=2232): Exception occurred processing WSGI script '/home/ubuntu/src/website/wsgi.py'.
[Fri Sep 29 17:35:36.041168 2017] [wsgi:error] [pid 2232:tid 139879227217664] [remote 155.35.47.150:9515] Traceback (most recent call last):
[Fri Sep 29 17:35:36.041184 2017] [wsgi:error] [pid 2232:tid 139879227217664] [remote 155.35.47.150:9515]   File "/home/ubuntu/src/website/wsgi.py", line 16, in <module>
[Fri Sep 29 17:35:36.041207 2017] [wsgi:error] [pid 2232:tid 139879227217664] [remote 155.35.47.150:9515]     application = get_wsgi_application()
[Fri Sep 29 17:35:36.041214 2017] [wsgi:error] [pid 2232:tid 139879227217664] [remote 155.35.47.150:9515]   File "/home/ubuntu/dev/lib/python3.5/site-packages/django/core/wsgi.py", line 13, in get_wsgi_application
[Fri Sep 29 17:35:36.041224 2017] [wsgi:error] [pid 2232:tid 139879227217664] [remote 155.35.47.150:9515]     django.setup()
[Fri Sep 29 17:35:36.041229 2017] [wsgi:error] [pid 2232:tid 139879227217664] [remote 155.35.47.150:9515]   File "/home/ubuntu/dev/lib/python3.5/site-packages/django/__init__.py", line 17, in setup
[Fri Sep 29 17:35:36.041237 2017] [wsgi:error] [pid 2232:tid 139879227217664] [remote 155.35.47.150:9515]     configure_logging(settings.LOGGING_CONFIG, settings.LOGGING)
[Fri Sep 29 17:35:36.041242 2017] [wsgi:error] [pid 2232:tid 139879227217664] [remote 155.35.47.150:9515]   File "/home/ubuntu/dev/lib/python3.5/site-packages/django/conf/__init__.py", line 55, in __getattr__
[Fri Sep 29 17:35:36.041251 2017] [wsgi:error] [pid 2232:tid 139879227217664] [remote 155.35.47.150:9515]     self._setup(name)
[Fri Sep 29 17:35:36.041255 2017] [wsgi:error] [pid 2232:tid 139879227217664] [remote 155.35.47.150:9515]   File "/home/ubuntu/dev/lib/python3.5/site-packages/django/conf/__init__.py", line 43, in _setup
[Fri Sep 29 17:35:36.041263 2017] [wsgi:error] [pid 2232:tid 139879227217664] [remote 155.35.47.150:9515]     self._wrapped = Settings(settings_module)
[Fri Sep 29 17:35:36.041267 2017] [wsgi:error] [pid 2232:tid 139879227217664] [remote 155.35.47.150:9515]   File "/home/ubuntu/dev/lib/python3.5/site-packages/django/conf/__init__.py", line 99, in __init__
[Fri Sep 29 17:35:36.041286 2017] [wsgi:error] [pid 2232:tid 139879227217664] [remote 155.35.47.150:9515]     mod = importlib.import_module(self.SETTINGS_MODULE)
[Fri Sep 29 17:35:36.041291 2017] [wsgi:error] [pid 2232:tid 139879227217664] [remote 155.35.47.150:9515]   File "/usr/lib/python2.7/importlib/__init__.py", line 37, in import_module
[Fri Sep 29 17:35:36.041312 2017] [wsgi:error] [pid 2232:tid 139879227217664] [remote 155.35.47.150:9515]     __import__(name)
[Fri Sep 29 17:35:36.041343 2017] [wsgi:error] [pid 2232:tid 139879227217664] [remote 155.35.47.150:9515] ImportError: No module named website.settings
[Fri Sep 29 17:45:26.809830 2017] [mpm_event:notice] [pid 2229:tid 139879453202304] AH00491: caught SIGTERM, shutting down
[Fri Sep 29 17:45:26.891731 2017] [wsgi:warn] [pid 2461:tid 140364878419840] mod_wsgi: Compiled for Python/2.7.11.
[Fri Sep 29 17:45:26.891782 2017] [wsgi:warn] [pid 2461:tid 140364878419840] mod_wsgi: Runtime using Python/2.7.12.
[Fri Sep 29 17:45:26.892390 2017] [mpm_event:notice] [pid 2461:tid 140364878419840] AH00489: Apache/2.4.18 (Ubuntu) mod_wsgi/4.3.0 Python/2.7.12 configured -- resuming normal operations
[Fri Sep 29 17:45:26.892406 2017] [core:notice] [pid 2461:tid 140364878419840] AH00094: Command line: '/usr/sbin/apache2'
[Fri Sep 29 17:45:35.072636 2017] [wsgi:error] [pid 2464:tid 140364770023168] /home/ubuntu/src//db.sqlite3
[Fri Sep 29 17:45:35.154228 2017] [wsgi:error] [pid 2464:tid 140364770023168] /home/ubuntu/src//db.sqlite3
[Fri Sep 29 17:45:35.154906 2017] [wsgi:error] [pid 2464:tid 140364770023168] bjagjibgbcbi
[Fri Sep 29 17:45:35.161322 2017] [wsgi:error] [pid 2464:tid 140364770023168] bjagjibgbccb
[Fri Sep 29 17:45:35.167364 2017] [wsgi:error] [pid 2464:tid 140364770023168] bjagjibgbaeb
[Fri Sep 29 17:45:35.173308 2017] [wsgi:error] [pid 2464:tid 140364770023168] bjagjibgbcad
[Fri Sep 29 17:45:35.179203 2017] [wsgi:error] [pid 2464:tid 140364770023168] bjagjibgbcag
[Fri Sep 29 17:45:35.185281 2017] [wsgi:error] [pid 2464:tid 140364770023168] bjagjibgbcdf
[Fri Sep 29 17:45:35.191357 2017] [wsgi:error] [pid 2464:tid 140364770023168] bjagjibgbcaj
[Fri Sep 29 17:45:35.197836 2017] [wsgi:error] [pid 2464:tid 140364770023168] bjagjibgbcdd
[Fri Sep 29 17:45:35.211901 2017] [wsgi:error] [pid 2464:tid 140364770023168] /usr/lib/python2.7/importlib/__init__.py:37: RemovedInDjango110Warning: django.core.context_processors is deprecated in favor of django.template.context_processors.
[Fri Sep 29 17:45:35.211911 2017] [wsgi:error] [pid 2464:tid 140364770023168]   __import__(name)
[Fri Sep 29 17:45:35.211913 2017] [wsgi:error] [pid 2464:tid 140364770023168] 
[Fri Sep 29 17:51:07.086983 2017] [mpm_event:notice] [pid 2461:tid 140364878419840] AH00491: caught SIGTERM, shutting down
[Fri Sep 29 17:51:07.191610 2017] [wsgi:warn] [pid 2856:tid 139686723766144] mod_wsgi: Compiled for Python/3.5.1+.
[Fri Sep 29 17:51:07.191652 2017] [wsgi:warn] [pid 2856:tid 139686723766144] mod_wsgi: Runtime using Python/3.5.2.
[Fri Sep 29 17:51:07.193365 2017] [mpm_event:notice] [pid 2856:tid 139686723766144] AH00489: Apache/2.4.18 (Ubuntu) mod_wsgi/4.3.0 Python/3.5.2 configured -- resuming normal operations
[Fri Sep 29 17:51:07.193383 2017] [core:notice] [pid 2856:tid 139686723766144] AH00094: Command line: '/usr/sbin/apache2'
[Fri Sep 29 17:51:07.280412 2017] [wsgi:error] [pid 2859:tid 139686723766144] mod_wsgi (pid=2859): Call to 'site.addsitedir()' failed for '(null)', stopping.
[Fri Sep 29 17:51:07.280446 2017] [wsgi:error] [pid 2859:tid 139686723766144] mod_wsgi (pid=2859): Call to 'site.addsitedir()' failed for '/home/ubuntu/dev/lib/python3.5/site-packages'.
[Fri Sep 29 17:51:16.298725 2017] [mpm_event:notice] [pid 2856:tid 139686723766144] AH00491: caught SIGTERM, shutting down
[Fri Sep 29 17:51:17.306920 2017] [wsgi:warn] [pid 3014:tid 139733606832000] mod_wsgi: Compiled for Python/3.5.1+.
[Fri Sep 29 17:51:17.306961 2017] [wsgi:warn] [pid 3014:tid 139733606832000] mod_wsgi: Runtime using Python/3.5.2.
[Fri Sep 29 17:51:17.307585 2017] [mpm_event:notice] [pid 3014:tid 139733606832000] AH00489: Apache/2.4.18 (Ubuntu) mod_wsgi/4.3.0 Python/3.5.2 configured -- resuming normal operations
[Fri Sep 29 17:51:17.307601 2017] [core:notice] [pid 3014:tid 139733606832000] AH00094: Command line: '/usr/sbin/apache2'
[Fri Sep 29 17:51:17.378012 2017] [wsgi:error] [pid 3017:tid 139733606832000] mod_wsgi (pid=3017): Call to 'site.addsitedir()' failed for '(null)', stopping.
[Fri Sep 29 17:51:17.378049 2017] [wsgi:error] [pid 3017:tid 139733606832000] mod_wsgi (pid=3017): Call to 'site.addsitedir()' failed for '/home/ubuntu/dev/lib/python3.5/site-packages'.
[Fri Sep 29 17:51:23.251268 2017] [wsgi:error] [pid 3017:tid 139733496628992] mod_wsgi (pid=3017): Call to 'site.addsitedir()' failed for '(null)', stopping.
[Fri Sep 29 17:51:23.251298 2017] [wsgi:error] [pid 3017:tid 139733496628992] mod_wsgi (pid=3017): Call to 'site.addsitedir()' failed for '/home/ubuntu/dev/lib/python3.5/site-packages'.
[Fri Sep 29 17:51:23.251858 2017] [wsgi:error] [pid 3017:tid 139733496628992] [remote 155.35.47.150:60213] mod_wsgi (pid=3017): Target WSGI script '/home/ubuntu/src/website/wsgi.py' cannot be loaded as Python module.
[Fri Sep 29 17:51:23.251883 2017] [wsgi:error] [pid 3017:tid 139733496628992] [remote 155.35.47.150:60213] mod_wsgi (pid=3017): Exception occurred processing WSGI script '/home/ubuntu/src/website/wsgi.py'.
[Fri Sep 29 17:51:23.252067 2017] [wsgi:error] [pid 3017:tid 139733496628992] [remote 155.35.47.150:60213] Traceback (most recent call last):
[Fri Sep 29 17:51:23.252089 2017] [wsgi:error] [pid 3017:tid 139733496628992] [remote 155.35.47.150:60213]   File "/home/ubuntu/src/website/wsgi.py", line 17, in <module>
[Fri Sep 29 17:51:23.252093 2017] [wsgi:error] [pid 3017:tid 139733496628992] [remote 155.35.47.150:60213]     from django.core.wsgi import get_wsgi_application
[Fri Sep 29 17:51:23.252106 2017] [wsgi:error] [pid 3017:tid 139733496628992] [remote 155.35.47.150:60213] ImportError: No module named 'django'
[Fri Sep 29 17:51:26.508322 2017] [wsgi:error] [pid 3017:tid 139733379041024] [remote 155.35.47.150:60213] mod_wsgi (pid=3017): Target WSGI script '/home/ubuntu/src/website/wsgi.py' cannot be loaded as Python module.
[Fri Sep 29 17:51:26.508374 2017] [wsgi:error] [pid 3017:tid 139733379041024] [remote 155.35.47.150:60213] mod_wsgi (pid=3017): Exception occurred processing WSGI script '/home/ubuntu/src/website/wsgi.py'.
[Fri Sep 29 17:51:26.508449 2017] [wsgi:error] [pid 3017:tid 139733379041024] [remote 155.35.47.150:60213] Traceback (most recent call last):
[Fri Sep 29 17:51:26.508469 2017] [wsgi:error] [pid 3017:tid 139733379041024] [remote 155.35.47.150:60213]   File "/home/ubuntu/src/website/wsgi.py", line 17, in <module>
[Fri Sep 29 17:51:26.508472 2017] [wsgi:error] [pid 3017:tid 139733379041024] [remote 155.35.47.150:60213]     from django.core.wsgi import get_wsgi_application
[Fri Sep 29 17:51:26.508488 2017] [wsgi:error] [pid 3017:tid 139733379041024] [remote 155.35.47.150:60213] ImportError: No module named 'django'
[Fri Sep 29 18:00:50.357968 2017] [mpm_event:notice] [pid 3014:tid 139733606832000] AH00491: caught SIGTERM, shutting down
[Fri Sep 29 18:00:51.368876 2017] [wsgi:warn] [pid 3192:tid 139970174928768] mod_wsgi: Compiled for Python/3.5.1+.
[Fri Sep 29 18:00:51.368914 2017] [wsgi:warn] [pid 3192:tid 139970174928768] mod_wsgi: Runtime using Python/3.5.2.
[Fri Sep 29 18:00:51.369523 2017] [mpm_event:notice] [pid 3192:tid 139970174928768] AH00489: Apache/2.4.18 (Ubuntu) mod_wsgi/4.3.0 Python/3.5.2 configured -- resuming normal operations
[Fri Sep 29 18:00:51.369541 2017] [core:notice] [pid 3192:tid 139970174928768] AH00094: Command line: '/usr/sbin/apache2'
[Fri Sep 29 18:00:51.442392 2017] [wsgi:error] [pid 3195:tid 139970174928768] mod_wsgi (pid=3195): Call to 'site.addsitedir()' failed for '(null)', stopping.
[Fri Sep 29 18:00:51.442428 2017] [wsgi:error] [pid 3195:tid 139970174928768] mod_wsgi (pid=3195): Call to 'site.addsitedir()' failed for '/home/ubuntu/dev/lib/python3.5/site-packages'.
[Fri Sep 29 18:01:02.993592 2017] [wsgi:error] [pid 3195:tid 139970064725760] mod_wsgi (pid=3195): Call to 'site.addsitedir()' failed for '(null)', stopping.
[Fri Sep 29 18:01:02.993624 2017] [wsgi:error] [pid 3195:tid 139970064725760] mod_wsgi (pid=3195): Call to 'site.addsitedir()' failed for '/home/ubuntu/dev/lib/python3.5/site-packages'.
[Fri Sep 29 18:01:02.994205 2017] [wsgi:error] [pid 3195:tid 139970064725760] [remote 155.35.47.150:31306] mod_wsgi (pid=3195): Target WSGI script '/home/ubuntu/src/website/wsgi.py' cannot be loaded as Python module.
[Fri Sep 29 18:01:02.994241 2017] [wsgi:error] [pid 3195:tid 139970064725760] [remote 155.35.47.150:31306] mod_wsgi (pid=3195): Exception occurred processing WSGI script '/home/ubuntu/src/website/wsgi.py'.
[Fri Sep 29 18:01:02.994408 2017] [wsgi:error] [pid 3195:tid 139970064725760] [remote 155.35.47.150:31306] Traceback (most recent call last):
[Fri Sep 29 18:01:02.994431 2017] [wsgi:error] [pid 3195:tid 139970064725760] [remote 155.35.47.150:31306]   File "/home/ubuntu/src/website/wsgi.py", line 17, in <module>
[Fri Sep 29 18:01:02.994434 2017] [wsgi:error] [pid 3195:tid 139970064725760] [remote 155.35.47.150:31306]     from django.core.wsgi import get_wsgi_application
[Fri Sep 29 18:01:02.994447 2017] [wsgi:error] [pid 3195:tid 139970064725760] [remote 155.35.47.150:31306] ImportError: No module named 'django'
[Fri Sep 29 18:07:56.306032 2017] [mpm_event:notice] [pid 3192:tid 139970174928768] AH00491: caught SIGTERM, shutting down
[Fri Sep 29 18:07:57.312461 2017] [wsgi:warn] [pid 3429:tid 140361392232320] mod_wsgi: Compiled for Python/3.5.1+.
[Fri Sep 29 18:07:57.312501 2017] [wsgi:warn] [pid 3429:tid 140361392232320] mod_wsgi: Runtime using Python/3.5.2.
[Fri Sep 29 18:07:57.313114 2017] [mpm_event:notice] [pid 3429:tid 140361392232320] AH00489: Apache/2.4.18 (Ubuntu) mod_wsgi/4.3.0 Python/3.5.2 configured -- resuming normal operations
[Fri Sep 29 18:07:57.313132 2017] [core:notice] [pid 3429:tid 140361392232320] AH00094: Command line: '/usr/sbin/apache2'
[Fri Sep 29 18:07:57.381857 2017] [wsgi:error] [pid 3432:tid 140361392232320] mod_wsgi (pid=3432): Call to 'site.addsitedir()' failed for '(null)', stopping.
[Fri Sep 29 18:07:57.381889 2017] [wsgi:error] [pid 3432:tid 140361392232320] mod_wsgi (pid=3432): Call to 'site.addsitedir()' failed for '/home/ubuntu/dev/lib/python3.5/site-packages'.
[Fri Sep 29 18:08:05.196031 2017] [wsgi:error] [pid 3432:tid 140361282029312] mod_wsgi (pid=3432): Call to 'site.addsitedir()' failed for '(null)', stopping.
[Fri Sep 29 18:08:05.196067 2017] [wsgi:error] [pid 3432:tid 140361282029312] mod_wsgi (pid=3432): Call to 'site.addsitedir()' failed for '/home/ubuntu/dev/lib/python3.5/site-packages'.
[Fri Sep 29 18:08:05.196667 2017] [wsgi:error] [pid 3432:tid 140361282029312] [remote 155.35.47.150:55392] mod_wsgi (pid=3432): Target WSGI script '/home/ubuntu/src/website/wsgi.py' cannot be loaded as Python module.
[Fri Sep 29 18:08:05.196692 2017] [wsgi:error] [pid 3432:tid 140361282029312] [remote 155.35.47.150:55392] mod_wsgi (pid=3432): Exception occurred processing WSGI script '/home/ubuntu/src/website/wsgi.py'.
[Fri Sep 29 18:08:05.196853 2017] [wsgi:error] [pid 3432:tid 140361282029312] [remote 155.35.47.150:55392] Traceback (most recent call last):
[Fri Sep 29 18:08:05.196873 2017] [wsgi:error] [pid 3432:tid 140361282029312] [remote 155.35.47.150:55392]   File "/home/ubuntu/src/website/wsgi.py", line 17, in <module>
[Fri Sep 29 18:08:05.196877 2017] [wsgi:error] [pid 3432:tid 140361282029312] [remote 155.35.47.150:55392]     from django.core.wsgi import get_wsgi_application
[Fri Sep 29 18:08:05.196889 2017] [wsgi:error] [pid 3432:tid 140361282029312] [remote 155.35.47.150:55392] ImportError: No module named 'django'
[Fri Sep 29 18:10:33.196612 2017] [mpm_event:notice] [pid 3429:tid 140361392232320] AH00491: caught SIGTERM, shutting down
[Fri Sep 29 18:10:34.206905 2017] [wsgi:warn] [pid 3606:tid 140495107041152] mod_wsgi: Compiled for Python/3.5.1+.
[Fri Sep 29 18:10:34.206946 2017] [wsgi:warn] [pid 3606:tid 140495107041152] mod_wsgi: Runtime using Python/3.5.2.
[Fri Sep 29 18:10:34.207601 2017] [mpm_event:notice] [pid 3606:tid 140495107041152] AH00489: Apache/2.4.18 (Ubuntu) mod_wsgi/4.3.0 Python/3.5.2 configured -- resuming normal operations
[Fri Sep 29 18:10:34.207616 2017] [core:notice] [pid 3606:tid 140495107041152] AH00094: Command line: '/usr/sbin/apache2'
[Fri Sep 29 18:10:34.282173 2017] [wsgi:error] [pid 3609:tid 140495107041152] mod_wsgi (pid=3609): Call to 'site.addsitedir()' failed for '(null)', stopping.
[Fri Sep 29 18:10:34.282207 2017] [wsgi:error] [pid 3609:tid 140495107041152] mod_wsgi (pid=3609): Call to 'site.addsitedir()' failed for '/home/ubuntu/dev/lib/python3.5/site-packages'.
[Fri Sep 29 18:10:38.988001 2017] [wsgi:error] [pid 3609:tid 140494996838144] mod_wsgi (pid=3609): Call to 'site.addsitedir()' failed for '(null)', stopping.
[Fri Sep 29 18:10:38.988033 2017] [wsgi:error] [pid 3609:tid 140494996838144] mod_wsgi (pid=3609): Call to 'site.addsitedir()' failed for '/home/ubuntu/dev/lib/python3.5/site-packages'.
[Fri Sep 29 18:10:38.988664 2017] [wsgi:error] [pid 3609:tid 140494996838144] [remote 155.35.47.150:57478] mod_wsgi (pid=3609): Target WSGI script '/home/ubuntu/src/website/wsgi.py' cannot be loaded as Python module.
[Fri Sep 29 18:10:38.988689 2017] [wsgi:error] [pid 3609:tid 140494996838144] [remote 155.35.47.150:57478] mod_wsgi (pid=3609): Exception occurred processing WSGI script '/home/ubuntu/src/website/wsgi.py'.
[Fri Sep 29 18:10:38.988852 2017] [wsgi:error] [pid 3609:tid 140494996838144] [remote 155.35.47.150:57478] Traceback (most recent call last):
[Fri Sep 29 18:10:38.988874 2017] [wsgi:error] [pid 3609:tid 140494996838144] [remote 155.35.47.150:57478]   File "/home/ubuntu/src/website/wsgi.py", line 17, in <module>
[Fri Sep 29 18:10:38.988877 2017] [wsgi:error] [pid 3609:tid 140494996838144] [remote 155.35.47.150:57478]     from django.core.wsgi import get_wsgi_application
[Fri Sep 29 18:10:38.988902 2017] [wsgi:error] [pid 3609:tid 140494996838144] [remote 155.35.47.150:57478] ImportError: No module named 'django'
[Fri Sep 29 18:20:31.411452 2017] [mpm_event:notice] [pid 3606:tid 140495107041152] AH00491: caught SIGTERM, shutting down
[Fri Sep 29 18:29:23.089981 2017] [wsgi:warn] [pid 3908:tid 140181456758656] mod_wsgi: Compiled for Python/3.5.1+.
[Fri Sep 29 18:29:23.090022 2017] [wsgi:warn] [pid 3908:tid 140181456758656] mod_wsgi: Runtime using Python/3.5.2.
[Fri Sep 29 18:29:23.090638 2017] [mpm_event:notice] [pid 3908:tid 140181456758656] AH00489: Apache/2.4.18 (Ubuntu) mod_wsgi/4.3.0 Python/3.5.2 configured -- resuming normal operations
[Fri Sep 29 18:29:23.090661 2017] [core:notice] [pid 3908:tid 140181456758656] AH00094: Command line: '/usr/sbin/apache2'
[Fri Sep 29 18:29:23.160058 2017] [wsgi:error] [pid 3911:tid 140181456758656] mod_wsgi (pid=3911): Call to 'site.addsitedir()' failed for '(null)', stopping.
[Fri Sep 29 18:29:23.160091 2017] [wsgi:error] [pid 3911:tid 140181456758656] mod_wsgi (pid=3911): Call to 'site.addsitedir()' failed for 'python-home=/home/ubuntu/dev/lib/python3.5'.
[Fri Sep 29 18:29:23.160664 2017] [wsgi:error] [pid 3911:tid 140181456758656] mod_wsgi (pid=3911): Target WSGI script '/home/ubuntu/src/website/wsgi.py' cannot be loaded as Python module.
[Fri Sep 29 18:29:23.160701 2017] [wsgi:error] [pid 3911:tid 140181456758656] mod_wsgi (pid=3911): Exception occurred processing WSGI script '/home/ubuntu/src/website/wsgi.py'.
[Fri Sep 29 18:29:23.166700 2017] [wsgi:error] [pid 3911:tid 140181456758656] Traceback (most recent call last):
[Fri Sep 29 18:29:23.166724 2017] [wsgi:error] [pid 3911:tid 140181456758656]   File "/home/ubuntu/src/website/wsgi.py", line 17, in <module>
[Fri Sep 29 18:29:23.166728 2017] [wsgi:error] [pid 3911:tid 140181456758656]     from django.core.wsgi import get_wsgi_application
[Fri Sep 29 18:29:23.166741 2017] [wsgi:error] [pid 3911:tid 140181456758656] ImportError: No module named 'django'
[Fri Sep 29 18:29:29.358815 2017] [wsgi:error] [pid 3911:tid 140181312714496] [remote 155.35.47.150:55163] mod_wsgi (pid=3911): Target WSGI script '/home/ubuntu/src/website/wsgi.py' cannot be loaded as Python module.
[Fri Sep 29 18:29:29.358880 2017] [wsgi:error] [pid 3911:tid 140181312714496] [remote 155.35.47.150:55163] mod_wsgi (pid=3911): Exception occurred processing WSGI script '/home/ubuntu/src/website/wsgi.py'.
[Fri Sep 29 18:29:29.358957 2017] [wsgi:error] [pid 3911:tid 140181312714496] [remote 155.35.47.150:55163] Traceback (most recent call last):
[Fri Sep 29 18:29:29.358979 2017] [wsgi:error] [pid 3911:tid 140181312714496] [remote 155.35.47.150:55163]   File "/home/ubuntu/src/website/wsgi.py", line 17, in <module>
[Fri Sep 29 18:29:29.358992 2017] [wsgi:error] [pid 3911:tid 140181312714496] [remote 155.35.47.150:55163]     from django.core.wsgi import get_wsgi_application
[Fri Sep 29 18:29:29.359009 2017] [wsgi:error] [pid 3911:tid 140181312714496] [remote 155.35.47.150:55163] ImportError: No module named 'django'
[Fri Sep 29 18:38:21.792333 2017] [mpm_event:notice] [pid 3908:tid 140181456758656] AH00491: caught SIGTERM, shutting down
[Fri Sep 29 18:38:22.807996 2017] [wsgi:warn] [pid 4392:tid 140174585517952] mod_wsgi: Compiled for Python/3.5.1+.
[Fri Sep 29 18:38:22.808033 2017] [wsgi:warn] [pid 4392:tid 140174585517952] mod_wsgi: Runtime using Python/3.5.2.
[Fri Sep 29 18:38:22.808594 2017] [mpm_event:notice] [pid 4392:tid 140174585517952] AH00489: Apache/2.4.18 (Ubuntu) mod_wsgi/4.3.0 Python/3.5.2 configured -- resuming normal operations
[Fri Sep 29 18:38:22.808613 2017] [core:notice] [pid 4392:tid 140174585517952] AH00094: Command line: '/usr/sbin/apache2'
[Fri Sep 29 18:38:22.879892 2017] [wsgi:error] [pid 4395:tid 140174585517952] mod_wsgi (pid=4395): Call to 'site.addsitedir()' failed for '(null)', stopping.
[Fri Sep 29 18:38:22.879925 2017] [wsgi:error] [pid 4395:tid 140174585517952] mod_wsgi (pid=4395): Call to 'site.addsitedir()' failed for 'python-home=/home/ubuntu/dev/lib/python3.5'.
[Fri Sep 29 18:38:22.880491 2017] [wsgi:error] [pid 4395:tid 140174585517952] mod_wsgi (pid=4395): Target WSGI script '/home/ubuntu/src/website/wsgi.py' cannot be loaded as Python module.
[Fri Sep 29 18:38:22.880521 2017] [wsgi:error] [pid 4395:tid 140174585517952] mod_wsgi (pid=4395): Exception occurred processing WSGI script '/home/ubuntu/src/website/wsgi.py'.
[Fri Sep 29 18:38:22.886719 2017] [wsgi:error] [pid 4395:tid 140174585517952] Traceback (most recent call last):
[Fri Sep 29 18:38:22.886747 2017] [wsgi:error] [pid 4395:tid 140174585517952]   File "/home/ubuntu/src/website/wsgi.py", line 17, in <module>
[Fri Sep 29 18:38:22.886751 2017] [wsgi:error] [pid 4395:tid 140174585517952]     from django.core.wsgi import get_wsgi_application
[Fri Sep 29 18:38:22.886764 2017] [wsgi:error] [pid 4395:tid 140174585517952] ImportError: No module named 'django'
[Fri Sep 29 18:38:28.342829 2017] [wsgi:error] [pid 4395:tid 140174441473792] [remote 155.35.47.150:18658] mod_wsgi (pid=4395): Target WSGI script '/home/ubuntu/src/website/wsgi.py' cannot be loaded as Python module.
[Fri Sep 29 18:38:28.342890 2017] [wsgi:error] [pid 4395:tid 140174441473792] [remote 155.35.47.150:18658] mod_wsgi (pid=4395): Exception occurred processing WSGI script '/home/ubuntu/src/website/wsgi.py'.
[Fri Sep 29 18:38:28.342961 2017] [wsgi:error] [pid 4395:tid 140174441473792] [remote 155.35.47.150:18658] Traceback (most recent call last):
[Fri Sep 29 18:38:28.342981 2017] [wsgi:error] [pid 4395:tid 140174441473792] [remote 155.35.47.150:18658]   File "/home/ubuntu/src/website/wsgi.py", line 17, in <module>
[Fri Sep 29 18:38:28.342985 2017] [wsgi:error] [pid 4395:tid 140174441473792] [remote 155.35.47.150:18658]     from django.core.wsgi import get_wsgi_application
[Fri Sep 29 18:38:28.343013 2017] [wsgi:error] [pid 4395:tid 140174441473792] [remote 155.35.47.150:18658] ImportError: No module named 'django'
[Fri Sep 29 18:39:40.778772 2017] [mpm_event:notice] [pid 4392:tid 140174585517952] AH00491: caught SIGTERM, shutting down
[Fri Sep 29 18:39:41.785609 2017] [wsgi:warn] [pid 4524:tid 139734579210112] mod_wsgi: Compiled for Python/3.5.1+.
[Fri Sep 29 18:39:41.785644 2017] [wsgi:warn] [pid 4524:tid 139734579210112] mod_wsgi: Runtime using Python/3.5.2.
[Fri Sep 29 18:39:41.786209 2017] [mpm_event:notice] [pid 4524:tid 139734579210112] AH00489: Apache/2.4.18 (Ubuntu) mod_wsgi/4.3.0 Python/3.5.2 configured -- resuming normal operations
[Fri Sep 29 18:39:41.786231 2017] [core:notice] [pid 4524:tid 139734579210112] AH00094: Command line: '/usr/sbin/apache2'
[Fri Sep 29 18:39:41.856179 2017] [wsgi:error] [pid 4527:tid 139734579210112] mod_wsgi (pid=4527): Call to 'site.addsitedir()' failed for '(null)', stopping.
[Fri Sep 29 18:39:41.856217 2017] [wsgi:error] [pid 4527:tid 139734579210112] mod_wsgi (pid=4527): Call to 'site.addsitedir()' failed for 'python-home=/home/ubuntu/dev/lib/python3.5/site-packages'.
[Fri Sep 29 18:39:41.856768 2017] [wsgi:error] [pid 4527:tid 139734579210112] mod_wsgi (pid=4527): Target WSGI script '/home/ubuntu/src/website/wsgi.py' cannot be loaded as Python module.
[Fri Sep 29 18:39:41.856795 2017] [wsgi:error] [pid 4527:tid 139734579210112] mod_wsgi (pid=4527): Exception occurred processing WSGI script '/home/ubuntu/src/website/wsgi.py'.
[Fri Sep 29 18:39:41.863184 2017] [wsgi:error] [pid 4527:tid 139734579210112] Traceback (most recent call last):
[Fri Sep 29 18:39:41.863209 2017] [wsgi:error] [pid 4527:tid 139734579210112]   File "/home/ubuntu/src/website/wsgi.py", line 17, in <module>
[Fri Sep 29 18:39:41.863212 2017] [wsgi:error] [pid 4527:tid 139734579210112]     from django.core.wsgi import get_wsgi_application
[Fri Sep 29 18:39:41.863226 2017] [wsgi:error] [pid 4527:tid 139734579210112] ImportError: No module named 'django'
[Fri Sep 29 18:39:46.772717 2017] [wsgi:error] [pid 4527:tid 139734435165952] [remote 155.35.47.150:56431] mod_wsgi (pid=4527): Target WSGI script '/home/ubuntu/src/website/wsgi.py' cannot be loaded as Python module.
[Fri Sep 29 18:39:46.772778 2017] [wsgi:error] [pid 4527:tid 139734435165952] [remote 155.35.47.150:56431] mod_wsgi (pid=4527): Exception occurred processing WSGI script '/home/ubuntu/src/website/wsgi.py'.
[Fri Sep 29 18:39:46.772851 2017] [wsgi:error] [pid 4527:tid 139734435165952] [remote 155.35.47.150:56431] Traceback (most recent call last):
[Fri Sep 29 18:39:46.772870 2017] [wsgi:error] [pid 4527:tid 139734435165952] [remote 155.35.47.150:56431]   File "/home/ubuntu/src/website/wsgi.py", line 17, in <module>
[Fri Sep 29 18:39:46.772874 2017] [wsgi:error] [pid 4527:tid 139734435165952] [remote 155.35.47.150:56431]     from django.core.wsgi import get_wsgi_application
[Fri Sep 29 18:39:46.772890 2017] [wsgi:error] [pid 4527:tid 139734435165952] [remote 155.35.47.150:56431] ImportError: No module named 'django'
[Fri Sep 29 18:43:16.811616 2017] [mpm_event:notice] [pid 4524:tid 139734579210112] AH00491: caught SIGTERM, shutting down
[Fri Sep 29 18:43:17.820042 2017] [wsgi:warn] [pid 4691:tid 140087457769344] mod_wsgi: Compiled for Python/3.5.1+.
[Fri Sep 29 18:43:17.820085 2017] [wsgi:warn] [pid 4691:tid 140087457769344] mod_wsgi: Runtime using Python/3.5.2.
[Fri Sep 29 18:43:17.820701 2017] [mpm_event:notice] [pid 4691:tid 140087457769344] AH00489: Apache/2.4.18 (Ubuntu) mod_wsgi/4.3.0 Python/3.5.2 configured -- resuming normal operations
[Fri Sep 29 18:43:17.820718 2017] [core:notice] [pid 4691:tid 140087457769344] AH00094: Command line: '/usr/sbin/apache2'
[Fri Sep 29 18:43:25.349784 2017] [wsgi:error] [pid 4694:tid 140087262865152] /home/ubuntu/src//db.sqlite3
[Fri Sep 29 18:43:25.412505 2017] [wsgi:error] [pid 4694:tid 140087262865152] /home/ubuntu/src//db.sqlite3
[Fri Sep 29 18:43:25.413117 2017] [wsgi:error] [pid 4694:tid 140087262865152] bjagjibgbcbi
[Fri Sep 29 18:43:25.419160 2017] [wsgi:error] [pid 4694:tid 140087262865152] bjagjibgbcad
[Fri Sep 29 18:43:25.425106 2017] [wsgi:error] [pid 4694:tid 140087262865152] bjagjibgbcdf
[Fri Sep 29 18:43:25.431167 2017] [wsgi:error] [pid 4694:tid 140087262865152] bjagjibgbcdd
[Fri Sep 29 18:43:25.437054 2017] [wsgi:error] [pid 4694:tid 140087262865152] bjagjibgbcag
[Fri Sep 29 18:43:25.442885 2017] [wsgi:error] [pid 4694:tid 140087262865152] bjagjibgbcaj
[Fri Sep 29 18:43:25.463053 2017] [wsgi:error] [pid 4694:tid 140087262865152] bjagjibgbccb
[Fri Sep 29 18:43:25.469302 2017] [wsgi:error] [pid 4694:tid 140087262865152] bjagjibgbaeb
[Fri Sep 29 18:43:25.478743 2017] [wsgi:error] [pid 4694:tid 140087262865152] /usr/lib/python3.5/importlib/__init__.py:126: RemovedInDjango110Warning: django.core.context_processors is deprecated in favor of django.template.context_processors.
[Fri Sep 29 18:43:25.478755 2017] [wsgi:error] [pid 4694:tid 140087262865152]   return _bootstrap._gcd_import(name[level:], package, level)
[Fri Sep 29 18:43:25.478760 2017] [wsgi:error] [pid 4694:tid 140087262865152] 
